Workbook

Sheet 機械別実績
B1: VDM | K1: Ngày làm việc
K2: Day | L2: 22 | M2: 15 | N2: 22 | X2: Note
L3: =L2 -> 22 | M3: =M2 -> 15 | N3: =N2 -> 22 | O3: =O2 -> 0 | P3: =P2 -> 0 | Q3: =Q2 -> 0 | R3: =R2 -> 0 | S3: =S2 -> 0 | ... W3: =W2 -> 0
A4: 工程 | B4: 台数 | C4: 機械 | D4: 設備名 | E4: ｼﾘｱﾙ№ | F4: ﾒｰｶｰ | G4: 機種 | H4: 標準稼働時間 | I4: 精度 | J4: 状態 | L4: T1 | M4: T2 | N4: T3 | O4: T4 | P4: T5 | Q4: T6 | R4: T7 | S4: T8 | T4: T9 | U4: T10 | V4: T11 | W4: T12
A5: LA | B5: 3 | C5: LA03 | D5: 汎用旋盤 | E5: 0168-AA | F5: TAKISAWA | G5: TAL-460 | H5: 910 | I5: B | L5: 21317 | M5: 15533 | N5: 24601
C6: LA04 | D6: 汎用旋盤 | E6: 0167-AA | F6: OKUMA | G6: LS450*800 | H6: 910 | I6: B | L6: 3020 | M6: 1811 | N6: 2553
C7: LA05 | D7: 汎用旋盤 | E7: 0784-AA | F7: TAKISAWA | G7: TAL-510L10 | H7: 910 | I7: B | L7: 20796 | M7: 15023 | N7: 23535
H10: =SUM(H5:H9) -> 2730 | J10: LA | K10: 合計 | L10: =SUM(L5:L9) -> 45133 | M10: =SUM(M5:M9) -> 32367 | N10: =SUM(N5:N9) -> 50689 | O10: =SUM(O5:O9) -> 0 | P10: =SUM(P5:P9) -> 0 | Q10: =SUM(Q5:Q9) -> 0 | R10: =SUM(R5:R9) -> 0 | S10: =SUM(S5:S9) -> 0 | ... W10: =SUM(W5:W9) -> 0
K11: 稼働率 | L11: =L10/($H$10*L3) -> 0.7514652 | M11: =M10/($H$10*M3) -> 0.79040293 | N11: =N10/($H$10*N3) -> 0.84397269 | O11: =O10/($H$10*O3) -> #DIV/0! | P11: =P10/($H$10*P3) -> #DIV/0! | Q11: =Q10/($H$10*Q3) -> #DIV/0! | R11: =R10/($H$10*R3) -> #DIV/0! | S11: =S10/($H$10*S3) -> #DIV/0! | ... W11: =W10/($H$10*W3) -> #DIV/0!
A12: MA | B12: 4 | C12: MA01 | D12: ﾌﾗｲｽ盤 | E12: 0690-AA | F12: SHIZUOKA | G12: SV-CH | H12: 910 | I12: B | L12: 21082 | M12: 15201 | N12: 25078
C13: MA02 | D13: ﾌﾗｲｽ盤 | E13: 0691-AA | F13: SHIZUOKA | G13: SV-CH | H13: 910 | I13: B | L13: 20751 | M13: 12066 | N13: 22910
C14: MA03 | D14: ﾌﾗｲｽ盤 | E14: 0174-AA | F14: NIIGATA | G14: 2UMB | H14: 910 | I14: B | L14: 14965 | M14: 11003 | N14: 15720
C15: MA04 | D15: ﾌﾗｲｽ盤 | E15: 0606-AA | F15: IWASHITA | G15: NK-1/2 | H15: 910 | I15: B | J15: 仕事無し/少ない | L15: 0 | M15: 0 | N15: 0
H17: =SUM(H12:H16) -> 3640 | J17: MA | K17: 合計 | L17: =SUM(L12:L16) -> 56798 | M17: =SUM(M12:M16) -> 38270 | N17: =SUM(N12:N16) -> 63708 | O17: =SUM(O12:O16) -> 0 | P17: =SUM(P12:P16) -> 0 | Q17: =SUM(Q12:Q16) -> 0 | R17: =SUM(R12:R16) -> 0 | S17: =SUM(S12:S16) -> 0 | ... W17: =SUM(W12:W16) -> 0
K18: 稼働率 | L18: =L17/($H$17*L3) -> 0.70926573 | M18: =M17/($H$17*M3) -> 0.70091575 | N18: =N17/($H$17*N3) -> 0.79555445 | O18: =O17/($H$17*O3) -> #DIV/0! | P18: =P17/($H$17*P3) -> #DIV/0! | Q18: =Q17/($H$17*Q3) -> #DIV/0! | R18: =R17/($H$17*R3) -> #DIV/0! | S18: =S17/($H$17*S3) -> #DIV/0! | ... W18: =W17/($H$17*W3) -> #DIV/0!
A19: BJ | B19: 5 | C19: BJ01 | D19: 精密ﾌﾗｲｽ盤 | E19: 0706-AA | F19: MAKINO | G19: KSJP-55 | H19: 910 | I19: B | L19: 15951 | M19: 14279 | N19: 23510
C20: BJ04 | D20: 精密ﾌﾗｲｽ盤 | E20: 0179-AA | F20: HASEGAWA | G20: HPF-B | H20: 910 | I20: B | L20: 8213 | M20: 7268 | N20: 6272
C21: BJ06 | D21: 精密ﾌﾗｲｽ盤 | E21: 0180-AA | F21: NIIGATA | G21: M-K2 | H21: 910 | I21: B | L21: 20771 | M21: 14098 | N21: 22062
C22: BJ07 | D22: 精密ﾌﾗｲｽ盤 | E22: 0707-AA | F22: MAKINO | G22: KSJP-55 | H22: 910 | I22: B | L22: 22592 | M22: 15368 | N22: 24459
C23: BJ08 | D23: 精密ﾌﾗｲｽ盤 | E23: 0792-AA | F23: MAKINO | G23: KVJP-55 | H23: 910 | I23: A | L23: 21452 | M23: 15070 | N23: 23842
H26: =SUM(H19:H25) -> 4550 | J26: BJ | K26: 合計 | L26: =SUM(L19:L25) -> 88979 | M26: =SUM(M19:M25) -> 66083 | N26: =SUM(N19:N25) -> 100145 | O26: =SUM(O19:O25) -> 0 | P26: =SUM(P19:P25) -> 0 | Q26: =SUM(Q19:Q25) -> 0 | R26: =SUM(R19:R24) -> 0 | S26: =SUM(S19:S25) -> 0 | T26: =SUM(T19:T25) -> 0 | U26: =SUM(U19:U25) -> 0 | V26: =SUM(V19:V25) -> 0 | W26: =SUM(W19:W25) -> 0
K27: 稼働率 | L27: =L26/($H$26*L3) -> 0.8889011 | M27: =M26/($H$26*M3) -> 0.96824908 | N27: =N26/($H$26*N3) -> 1.0004496 | O27: =O26/($H$26*O3) -> #DIV/0! | P27: =P26/($H$26*P3) -> #DIV/0! | Q27: =Q26/($H$26*Q3) -> #DIV/0! | R27: =R26/($H$26*R3) -> #DIV/0! | S27: =S26/($H$26*S3) -> #DIV/0! | ... W27: =W26/($H$26*W3) -> #DIV/0!
A28: DA | B28: 2 | C28: DA01 | D28: 卓上ボール盤 | E28: 0181-AA | F28: YOSHIDA(ＶＮＭ改造) | G28: XY座標付 | H28: 910 | I28: C | J28: 多量品穴加工用 | L28: 0 | M28: 0 | N28: 0
C29: DA04 | D29: ﾗｼﾞｱﾙﾎﾞｰﾙ盤 | E29: 0184-AA | F29: OKUMA | G29: DMB-YH152R | H29: 910 | I29: B | J29: ネジ加工専用 | L29: 8420 | M29: 6820 | N29: 9833
H31: =SUM(H28:H30) -> 1820 | J31: DA | K31: 合計 | L31: =SUM(L28:L30) -> 8420 | M31: =SUM(M28:M30) -> 6820 | N31: =SUM(N28:N30) -> 9833 | O31: =SUM(O28:O30) -> 0 | P31: =SUM(P28:P30) -> 0 | Q31: =SUM(Q28:Q30) -> 0 | R31: =SUM(R28:R30) -> 0 | S31: =SUM(S28:S30) -> 0 | ... W31: =SUM(W28:W30) -> 0
K32: 稼働率 | L32: =L31/($H$31*L3) -> 0.21028971 | M32: =M31/($H$31*M3) -> 0.24981685 | N32: =N31/($H$31*N3) -> 0.24557942 | O32: =O31/($H$31*O3) -> #DIV/0! | P32: =P31/($H$31*P3) -> #DIV/0! | Q32: =Q31/($H$31*Q3) -> #DIV/0! | R32: =R31/($H$31*R3) -> #DIV/0! | S32: =S31/($H$31*S3) -> #DIV/0! | ... W32: =W31/($H$31*W3) -> #DIV/0!
A33: HT | B33: 4 | C33: HT01 | D33: 電気炉(焼入れ) | E33: 0200-AA | F33: THERMAL | G33: RBM4/K | H33: 490 | I33: 対象外 | L33: 0 | M33: 0 | N33: 0
C34: HT02 | D34: 電気炉（焼戻し） | E34: 0201-AA | F34: THERMAL | G34: TL-4 | H34: 490 | I34: 対象外 | L34: 0 | M34: 0 | N34: 0
C35: HT05 | D35: 真空熱処理炉 | E35: 0781-AA | F35: NAKANIHON-RO | G35: NVF50P | H35: 490 | I35: 対象外 | L35: 14010 | M35: 9620 | N35: 15035
H37: =SUM(H33:H36) -> 1470 | J37: HT | K37: 合計 | L37: =SUM(L33:L36) -> 14010 | M37: =SUM(M33:M36) -> 9620 | N37: =SUM(N33:N36) -> 15035 | O37: =SUM(O33:O36) -> 0 | P37: =SUM(P33:P36) -> 0 | Q37: =SUM(Q33:Q36) -> 0 | R37: =SUM(R33:R36) -> 0 | S37: =SUM(S33:S36) -> 0 | ... W37: =SUM(W33:W36) -> 0
K38: 稼働率 | L38: =L37/($H$37*L3) -> 0.43320965 | M38: =M37/($H$37*M3) -> 0.43628118 | N38: =N37/($H$37*N3) -> 0.46490414 | O38: =O37/($H$37*O3) -> #DIV/0! | P38: =P37/($H$37*P3) -> #DIV/0! | Q38: =Q37/($H$37*Q3) -> #DIV/0! | R38: =R37/($H$37*R3) -> #DIV/0! | S38: =S37/($H$37*S3) -> #DIV/0! | ... W38: =W37/($H$37*W3) -> #DIV/0!
A39: LN | B39: 2 | C39: LN01 | D39: CNC旋盤 | E39: 0649-AA | F39: MAZAK | G39: QT Smart 200M | H39: 910 | I39: B | L39: 23009 | M39: 14812 | N39: 27047
C40: LN02 | D40: CNC旋盤 | E40: 0708-AA | F40: MAZAK | G40: QUICK TURN 200MY(500U) | H40: 910 | I40: B | L40: 25628 | M40: 20299 | N40: 30750
H42: =SUM(H39:H41) -> 1820 | J42: LN | K42: 合計 | L42: =SUM(L39:L41) -> 48637 | M42: =SUM(M39:M41) -> 35111 | N42: =SUM(N39:N41) -> 57797 | O42: =SUM(O39:O41) -> 0 | P42: =SUM(P39:P41) -> 0 | Q42: =SUM(Q39:Q41) -> 0 | R42: =SUM(R39:R41) -> 0 | S42: =SUM(S39:S41) -> 0 | ... W42: =SUM(W39:W41) -> 0
K43: 稼働率 | L43: =L42/($H$42*L2) -> 1.2147103 | M43: =M42/($H$42*M2) -> 1.2861172 | N43: =N42/($H$42*N2) -> 1.4434815 | O43: =O42/($H$42*O2) -> #DIV/0! | P43: =P42/($H$42*P2) -> #DIV/0! | Q43: =Q42/($H$42*Q2) -> #DIV/0! | R43: =R42/($H$42*R2) -> #DIV/0! | S43: =S42/($H$42*S2) -> #DIV/0! | ... W43: =W42/($H$42*W2) -> #DIV/0!
A44: MC | B44: 3 | C44: MC1 | D44: 一般ﾏｼﾆﾝｸﾞｾﾝﾀ | E44: 0645-AA | F44: MAZAK | G44: SMART430A | H44: 910 | I44: B | L44: 24069 | M44: 15339 | N44: 31366
C45: MC2 | D45: 一般ﾏｼﾆﾝｸﾞｾﾝﾀ | E45: 0669-AA | F45: MAZAK | G45: SMART430A | H45: 910 | I45: B | L45: 20892 | M45: 15143 | N45: 24112
C46: MC3 | D46: 高精度ﾏｼﾆﾝｸﾞｾﾝﾀ | E46: 0769-AA | F46: MAKINO | G46: V33i (3R システム) | H46: 910 | I46: B | L46: 24294 | M46: 17557 | N46: 30516
H49: =SUM(H44:H48) -> 2730 | J49: MC | K49: 合計 | L49: =SUM(L44:L48) -> 69255 | M49: =SUM(M44:M48) -> 48039 | N49: =SUM(N44:N48) -> 85994 | O49: =SUM(O44:O48) -> 0 | P49: =SUM(P44:P48) -> 0 | Q49: =SUM(Q44:Q48) -> 0 | R49: =SUM(R44:R48) -> 0 | S49: =SUM(S44:S48) -> 0 | ... W49: =SUM(W44:W48) -> 0
K50: 稼働率 | L50: =L49/($H$49*L2) -> 1.1530969 | M50: =M49/($H$49*M2) -> 1.1731136 | N50: =N49/($H$49*N2) -> 1.4318015 | O50: =O49/($H$49*O2) -> #DIV/0! | P50: =P49/($H$49*P2) -> #DIV/0! | Q50: =Q49/($H$49*Q2) -> #DIV/0! | R50: =R49/($H$49*R2) -> #DIV/0! | S50: =S49/($H$49*S2) -> #DIV/0! | ... W50: =W49/($H$49*W2) -> #DIV/0!
...

Sheet 指標1
A2: 1 | B2: 内作受注数量
A3: 内作受注数量 | B3: 1月 | C3: 2月 | D3: 3月 | E3: 4月 | F3: 5月 | G3: 6月 | H3: 7月 | I3: 8月 | J3: 9月 | K3: 10月 | L3: 11月 | M3: 12月
A4: số pcs nhận | B4: 37419 | C4: 18771 | D4: 42119
E5: ※1ヶ月の受注総数量（図面1枚で製作数量が10個の場合は10と報告の事）
A7: 2 | B7: 内作仕掛数量
A8: 内作仕掛数量 | B8: 1月 | C8: 2月 | D8: 3月 | E8: 4月 | F8: 5月 | G8: 6月 | H8: 7月 | I8: 8月 | J8: 9月 | K8: 10月 | L8: 11月 | M8: 12月
A9: số pcs tồn | B9: 33772 | C9: 31704 | D9: 35107
E10: ※月末時の仕掛り件数（図面1枚仕掛りで製作数量が10個の場合は10と報告の事）
A12: 3 | B12: 内作完了数量
A13: 内作完了数量 | B13: 1月 | C13: 2月 | D13: 3月 | E13: 4月 | F13: 5月 | G13: 6月 | H13: 7月 | I13: 8月 | J13: 9月 | K13: 10月 | L13: 11月 | M13: 12月
A14: số pcs hoàn thành | B14: 34099 | C14: 19956 | D14: 35124
E15: ※1ヶ月の完了総数量（図面1枚で製作数量が10個の場合は10と報告の事）
A17: 4 | B17: 内作受注図面枚数
A18: 内作受注図面枚数 | B18: 1月 | C18: 2月 | D18: 3月 | E18: 4月 | F18: 5月 | G18: 6月 | H18: 7月 | I18: 8月 | J18: 9月 | K18: 10月 | L18: 11月 | M18: 12月
A19: bản vẽ nhận | B19: 2874 | C19: 1546 | D19: 2402
E20: ※1ヶ月の受注図面総数
A22: 5 | B22: 内作仕掛図面枚数
A23: 内作仕掛図面枚数 | B23: 1月 | C23: 2月 | D23: 3月 | E23: 4月 | F23: 5月 | G23: 6月 | H23: 7月 | I23: 8月 | J23: 9月 | K23: 10月 | L23: 11月 | M23: 12月
A24: bản vẽ tồn | B24: 2586 | C24: 2542 | D24: 2571
E25: ※月末時の仕掛り図面枚数
A27: 6 | B27: 内作完了図面枚数
A28: 内作完了図面枚数 | B28: 1月 | C28: 2月 | D28: 3月 | E28: 4月 | F28: 5月 | G28: 6月 | H28: 7月 | I28: 8月 | J28: 9月 | K28: 10月 | L28: 11月 | M28: 12月 | N28: VDM
A29: bản vẽ hoàn thành | B29: 2412 | C29: 1563 | D29: 2232 | N29: =SUM(B29:M29) -> 6207 | W29: VDM | X29: =SUM(N29) -> 6207
E30: ※1ヶ月の完了図面総数 | W30: GCN | X30: =SUM(N34) -> 6287
A32: 7 | B32: 外作完了図面枚数
A33: 外作完了図面枚数 | B33: 1月 | C33: 2月 | D33: 3月 | E33: 4月 | F33: 5月 | G33: 6月 | H33: 7月 | I33: 8月 | J33: 9月 | K33: 10月 | L33: 11月 | M33: 12月 | N33: GCN
A34: bản vẽ GCN hoàn thành | B34: 2076 | C34: 1771 | D34: 2440 | N34: =SUM(B34:M34) -> 6287
E35: ※1ヶ月の依頼図面総数
A37: 8 | B37: 納期遵守率（初回納期回答に対する納期遵守率）
A38: 納期遵守率 | B38: 1月 | C38: 2月 | D38: 3月 | E38: 4月 | F38: 5月 | G38: 6月 | H38: 7月 | I38: 8月 | J38: 9月 | K38: 10月 | L38: 11月 | M38: 12月
A39: Tỷ lệ giao hàng đúng hạn | B39: 1 | C39: 1 | D39: 1
E40: ※納期遵守件数÷完了件数×100（小数点第一位まで報告の事）
A42: 9-1 | B42: L/T（平均）
A43: Bình quân | B43: 1月 | C43: 2月 | D43: 3月 | E43: 4月 | F43: 5月 | G43: 6月 | H43: 7月 | I43: 8月 | J43: 9月 | K43: 10月 | L43: 11月 | M43: 12月
A44: L/T | B44: 21.7 | C44: 21.2 | D44: 22.4
E45: ※受付～完了までの平均日数（小数点第一位まで報告の事）
B47: L/T（金型）
A48: Khuôn | B48: 1月 | C48: 2月 | D48: 3月 | E48: 4月 | F48: 5月 | G48: 6月 | H48: 7月 | I48: 8月 | J48: 9月 | K48: 10月 | L48: 11月 | M48: 12月
B49: 43.5 | C49: 49.7 | D49: 58.7
E50: ※受付～完了までの平均日数（小数点第一位まで報告の事）
...

Sheet 指標２(内作)
C1: ①工程別不良件数グラフの追加・・・可視化
C2: ②工程別不良率グラフの追加・・・可視化
C3: ③不良件数が１以上だと、赤色（自動）になります・・・見やすくする為
C4: ④工程不良報告書の提出（日文）
A6: 【内作】 | C6: 自動計算 | E6: 自動
B7: 工程不良件数、工程不良率
C8: 1月 | D8: 2月 | E8: 3月 | F8: 4月 | G8: 5月 | H8: 6月 | I8: 7月 | J8: 8月 | K8: 9月 | L8: 10月 | M8: 11月 | N8: 12月 | O8: Lũy kế
A9: ALL | B9: Số bản vẽ | C9: =C12+C15+C18+C21+C24+C27+C30+C33+C39+C42+C45+C48+C54+C36+C51 -> 6743 | D9: =D12+D15+D18+D21+D24+D27+D30+D33+D39+D42+D45+D48+D54+D36+D51 -> 4357 | E9: =E12+E15+E18+E21+E24+E27+E30+E33+E39+E42+E45+E48+E54+E36+E51 -> 6625 | O9: =SUM(C9:N9) -> 17725
B10: Số phế phẩm | C10: =C13+C16+C19+C22+C25+C28+C31+C34+C40+C43+C46+C49+C55+C37+C52 -> 0 | D10: =D13+D16+D19+D22+D25+D28+D31+D34+D40+D43+D46+D49+D55+D37+D52 -> 0 | E10: =E13+E16+E19+E22+E25+E28+E31+E34+E40+E43+E46+E49+E55+E37+E52 -> 1 | O10: =SUM(C10:N10) -> 1
B11: Tỷ lệ phế phẩm | C11: =C10/C9 -> 0 | D11: =D10/D9 -> 0 | E11: =E10/E9 -> 0.0001509434 | F11: =F10/F9 -> #DIV/0! | G11: =G10/G9 -> #DIV/0! | H11: =H10/H9 -> #DIV/0! | I11: =I10/I9 -> #DIV/0! | J11: =J10/J9 -> #DIV/0! | ... O11: =O10/O9 -> 5.6417489e-05
A12: LA （旋盤） MÁY TiỆN | B12: Số bản vẽ | C12: 453 | D12: 275 | E12: 425 | O12: =SUM(C12:N12) -> 1153
B13: Số phế phẩm | C13: 0 | D13: 0 | E13: 0 | O13: =SUM(C13:N13) -> 0
B14: Tỷ lệ phế phẩm | C14: =C13/C12 -> 0 | D14: =D13/D12 -> 0 | E14: =E13/E12 -> 0 | F14: =F13/F12 -> #DIV/0! | G14: =G13/G12 -> #DIV/0! | H14: =H13/H12 -> #DIV/0! | I14: =I13/I12 -> #DIV/0! | J14: =J13/J12 -> #DIV/0! | ... O14: =O13/O12 -> 0
A15: LN （NC旋盤） MÁY TIỆN CNC | B15: Số bản vẽ | C15: 78 | D15: 36 | E15: 100 | O15: =SUM(C15:N15) -> 214
B16: Số phế phẩm | C16: 0 | D16: 0 | E16: 0 | O16: =SUM(C16:N16) -> 0
B17: Tỷ lệ phế phẩm | C17: =C16/C15 -> 0 | D17: =D16/D15 -> 0 | E17: =E16/E15 -> 0 | F17: =F16/F15 -> #DIV/0! | G17: =G16/G15 -> #DIV/0! | H17: =H16/H15 -> #DIV/0! | I17: =I16/I15 -> #DIV/0! | J17: =J16/J15 -> #DIV/0! | ... O17: =O16/O15 -> 0
A18: MA （ﾌﾗｲｽ盤） MÁY PHAY | B18: Số bản vẽ | C18: 1081 | D18: 670 | E18: 1079 | O18: =SUM(C18:N18) -> 2830
B19: Số phế phẩm | C19: 0 | D19: 0 | E19: 0 | O19: =SUM(C19:N19) -> 0
B20: Tỷ lệ phế phẩm | C20: =C19/C18 -> 0 | D20: =D19/D18 -> 0 | E20: =E19/E18 -> 0 | F20: =F19/F18 -> #DIV/0! | G20: =G19/G18 -> #DIV/0! | H20: =H19/H18 -> #DIV/0! | I20: =I19/I18 -> #DIV/0! | J20: =J19/J18 -> #DIV/0! | ... O20: =O19/O18 -> 0
A21: DA （ﾎﾞｰﾙ盤） MÁY KHOAN | B21: Số bản vẽ | C21: 469 | D21: 355 | E21: 523 | O21: =SUM(C21:N21) -> 1347
B22: Số phế phẩm | C22: 0 | D22: 0 | E22: 0 | O22: =SUM(C22:N22) -> 0
B23: Tỷ lệ phế phẩm | C23: =C22/C21 -> 0 | D23: =D22/D21 -> 0 | E23: =E22/E21 -> 0 | F23: =F22/F21 -> #DIV/0! | G23: =G22/G21 -> #DIV/0! | H23: =H22/H21 -> #DIV/0! | I23: =I22/I21 -> #DIV/0! | J23: =J22/J21 -> #DIV/0! | ... O23: =O22/O21 -> 0
A24: BJ （精密ﾌﾗｲｽ盤） MÁY PHAY CHÍNH XÁC | B24: Số bản vẽ | C24: 1295 | D24: 899 | E24: 1309 | O24: =SUM(C24:N24) -> 3503
B25: Số phế phẩm | C25: 0 | D25: 0 | E25: 0 | O25: =SUM(C25:N25) -> 0
B26: Tỷ lệ phế phẩm | C26: =C25/C24 -> 0 | D26: =D25/D24 -> 0 | E26: =E25/E24 -> 0 | F26: =F25/F24 -> #DIV/0! | G26: =G25/G24 -> #DIV/0! | H26: =H25/H24 -> #DIV/0! | I26: =I25/I24 -> #DIV/0! | J26: =J25/J24 -> #DIV/0! | ... O26: =O25/O24 -> 0
A27: MC （ﾏｼﾆﾝｸﾞｾﾝﾀ） MÁY PHAY CNC MÁY PHAY TRUNG TÂM | B27: Số bản vẽ | C27: 258 | D27: 173 | E27: 316 | O27: =SUM(C27:N27) -> 747
B28: Số phế phẩm | C28: 0 | D28: 0 | E28: 0 | O28: =SUM(C28:N28) -> 0
B29: Tỷ lệ phế phẩm | C29: =C28/C27 -> 0 | D29: =D28/D27 -> 0 | E29: =E28/E27 -> 0 | F29: =F28/F27 -> #DIV/0! | G29: =G28/G27 -> #DIV/0! | H29: =H28/H27 -> #DIV/0! | I29: =I28/I27 -> #DIV/0! | J29: =J28/J27 -> #DIV/0! | ... O29: =O28/O27 -> 0
A30: GS （成形研削盤） MÁY MÀI TẠO HÌNH | B30: Số bản vẽ | C30: 1356 | D30: 878 | E30: 1275 | O30: =SUM(C30:N30) -> 3509
B31: Số phế phẩm | C31: 0 | D31: 0 | E31: 1 | O31: =SUM(C31:N31) -> 1
B32: Tỷ lệ phế phẩm | C32: =C31/C30 -> 0 | D32: =D31/D30 -> 0 | E32: =E31/E30 -> 0.00078431373 | F32: =F31/F30 -> #DIV/0! | G32: =G31/G30 -> #DIV/0! | H32: =H31/H30 -> #DIV/0! | I32: =I31/I30 -> #DIV/0! | J32: =J31/J30 -> #DIV/0! | ... O32: =O31/O30 -> 0.00028498148
A33: GR （円筒研削盤） MÁY MÀI TRÒN CÓ TÂM | B33: Số bản vẽ | C33: 348 | D33: 224 | E33: 247 | O33: =SUM(C33:N33) -> 819
B34: Số phế phẩm | C34: 0 | D34: 0 | E34: 0 | O34: =SUM(C34:N34) -> 0
B35: Tỷ lệ phế phẩm | C35: =C34/C33 -> 0 | D35: =D34/D33 -> 0 | E35: =E34/E33 -> 0 | F35: =F34/F33 -> #DIV/0! | G35: =G34/G33 -> #DIV/0! | H35: =H34/H33 -> #DIV/0! | I35: =I34/I33 -> #DIV/0! | J35: =J34/J33 -> #DIV/0! | ... O35: =O34/O33 -> 0
A36: GX （内径研削盤） | B36: 図面総数 | O36: =SUM(C36:N36) -> 0
B37: 不良件数 | O37: =SUM(C37:N37) -> 0
B38: 不良率 | C38: =C37/C36 -> #DIV/0! | D38: =D37/D36 -> #DIV/0! | E38: =E37/E36 -> #DIV/0! | F38: =F37/F36 -> #DIV/0! | G38: =G37/G36 -> #DIV/0! | H38: =H37/H36 -> #DIV/0! | I38: =I37/I36 -> #DIV/0! | J38: =J37/J36 -> #DIV/0! | ... O38: =O37/O36 -> #DIV/0!
A39: GC （ｾﾝﾀｰﾚｽ） MÁY MÀI TRÒN VÔ TÂM | B39: Số bản vẽ | C39: 190 | D39: 112 | E39: 165 | O39: =SUM(C39:N39) -> 467
B40: Số phế phẩm | C40: 0 | D40: 0 | E40: 0 | O40: =SUM(C40:N40) -> 0
B41: Tỷ lệ phế phẩm | C41: =C40/C39 -> 0 | D41: =D40/D39 -> 0 | E41: =E40/E39 -> 0 | F41: =F40/F39 -> #DIV/0! | G41: =G40/G39 -> #DIV/0! | H41: =H40/H39 -> #DIV/0! | I41: =I40/I39 -> #DIV/0! | J41: =J40/J39 -> #DIV/0! | ... O41: =O40/O39 -> 0
...

Sheet 指標２(外作)
D1: ①工程別不良件数グラフの追加・・・可視化
D2: ②工程別不良率グラフの追加・・・可視化
D3: ③不良件数が１以上だと、赤色（自動）になります・・・見やすくする為
B6: 【外作】 | D6: 自動計算 | F6: 自動
C7: 工程不良件数、工程不良率
A8: 業者No | B8: 業者名 | D8: 1月 | E8: 2月 | F8: 3月 | G8: 4月 | H8: 5月 | I8: 6月 | J8: 7月 | K8: 8月 | L8: 9月 | M8: 10月 | N8: 11月 | O8: 12月 | P8: Lũy kế
B9: ALL | C9: Số bản vẽ | D9: =SUM(D12,D15,D18,D21,D24,D27,D30,D33,D36,D39,D42,D45,D48,D51,D54,D57,D60,D63,D66,D69,D72,D75,D78,D81,D84,D87,D90,D93,D96,D99,D102) -> 2126 | E9: =SUM(E12,E15,E18,E21,E24,E27,E30,E33,E36,E39,E42,E45,E48,E51,E54,E57,E60,E63,E66,E69,E72,E75,E78,E81,E84,E87,E90,E93,E96,E99,E102) -> 1807 | F9: =SUM(F12,F15,F18,F21,F24,F27,F30,F33,F36,F39,F42,F45,F48,F51,F54,F57,F60,F63,F66,F69,F72,F75,F78,F81,F84,F87,F90,F93,F96,F99,F102) -> 2510 | G9: =SUM(G12,G15,G18,G21,G24,G27,G30,G33,G36,G39,G42,G45,G48,G51,G54,G57,G60,G63,G66,G69,G72,G75,G78,G81,G84,G87,G90,G93,G96,G99,G102) -> 0 | H9: =SUM(H12,H15,H18,H21,H24,H27,H30,H33,H36,H39,H42,H45,H48,H51,H54,H57,H60,H63,H66,H69,H72,H75,H78,H81,H84,H87,H90,H93,H96,H99,H102) -> 0 | I9: =SUM(I12,I15,I18,I21,I24,I27,I30,I33,I36,I39,I42,I45,I48,I51,I54,I57,I60,I63,I66,I69,I72,I75,I78,I81,I84,I87,I90,I93,I96,I99,I102) -> 0 | J9: =SUM(J12,J15,J18,J21,J24,J27,J30,J33,J36,J39,J42,J45,J48,J51,J54,J57,J60,J63,J66,J69,J72,J75,J78,J81,J84,J87,J90,J93,J96,J99,J102) -> 0 | K9: =SUM(K12,K15,K18,K21,K24,K27,K30,K33,K36,K39,K42,K45,K48,K51,K54,K57,K60,K63,K66,K69,K72,K75,K78,K81,K84,K87,K90,K93,K96,K99,K102) -> 0 | ... O9: =SUM(O12,O15,O18,O21,O24,O27,O30,O33,O36,O39,O42,O45,O48,O51,O54,O57,O60,O63,O66,O69,O72,O75,O78,O81,O84,O87,O90,O93,O96,O99,O102) -> 0 | P9: =SUM(D9:O9) -> 6443
C10: Số phế phẩm | D10: =SUM(D13,D16,D19,D22,D25,D28,D31,D34,D37,D40,D43,D46,D49,D52,D55,D58,D61,D64,D67,D70,D73,D76,D79,D82,D85,D88,D91,D94,D97,D100,D103) -> 0 | E10: =SUM(E13,E16,E19,E22,E25,E28,E31,E34,E37,E40,E43,E46,E49,E52,E55,E58,E61,E64,E67,E70,E73,E76,E79,E82,E85,E88,E91,E94,E97,E100,E103) -> 4 | F10: =SUM(F13,F16,F19,F22,F25,F28,F31,F34,F37,F40,F43,F46,F49,F52,F55,F58,F61,F64,F67,F70,F73,F76,F79,F82,F85,F88,F91,F94,F97,F100,F103) -> 4 | G10: =SUM(G13,G16,G19,G22,G25,G28,G31,G34,G37,G40,G43,G46,G49,G52,G55,G58,G61,G64,G67,G70,G73,G76,G79,G82,G85,G88,G91,G94,G97,G100,G103) -> 0 | H10: =SUM(H13,H16,H19,H22,H25,H28,H31,H34,H37,H40,H43,H46,H49,H52,H55,H58,H61,H64,H67,H70,H73,H76,H79,H82,H85,H88,H91,H94,H97,H100,H103) -> 0 | I10: =SUM(I13,I16,I19,I22,I25,I28,I31,I34,I37,I40,I43,I46,I49,I52,I55,I58,I61,I64,I67,I70,I73,I76,I79,I82,I85,I88,I91,I94,I97,I100,I103) -> 0 | J10: =SUM(J13,J16,J19,J22,J25,J28,J31,J34,J37,J40,J43,J46,J49,J52,J55,J58,J61,J64,J67,J70,J73,J76,J79,J82,J85,J88,J91,J94,J97,J100,J103) -> 0 | K10: =SUM(K13,K16,K19,K22,K25,K28,K31,K34,K37,K40,K43,K46,K49,K52,K55,K58,K61,K64,K67,K70,K73,K76,K79,K82,K85,K88,K91,K94,K97,K100,K103) -> 0 | ... O10: =SUM(O13,O16,O19,O22,O25,O28,O31,O34,O37,O40,O43,O46,O49,O52,O55,O58,O61,O64,O67,O70,O73,O76,O79,O82,O85,O88,O91,O94,O97,O100,O103) -> 0 | P10: =SUM(D10:O10) -> 8
C11: Tỷ lệ phế phẩm | D11: =D10/D9 -> 0 | E11: =E10/E9 -> 0.0022136137 | F11: =F10/F9 -> 0.0015936255 | G11: =G10/G9 -> #DIV/0! | H11: =H10/H9 -> #DIV/0! | I11: =I10/I9 -> #DIV/0! | J11: =J10/J9 -> #DIV/0! | K11: =K10/K9 -> #DIV/0! | ... P11: =P10/P9 -> 0.0012416576
A12: A0001 | B12: MMK | C12: Số bản vẽ | D12: 13 | E12: 0 | F12: 0 | P12: =SUM(D12:O12) -> 13
C13: Số phế phẩm | D13: 0 | E13: 0 | F13: 0 | P13: =SUM(D13:O13) -> 0
C14: Tỷ lệ phế phẩm | D14: =D13/D12 -> 0 | E14: =E13/E12 -> #DIV/0! | F14: =F13/F12 -> #DIV/0! | G14: =G13/G12 -> #DIV/0! | H14: =H13/H12 -> #DIV/0! | I14: =I13/I12 -> #DIV/0! | J14: =J13/J12 -> #DIV/0! | K14: =K13/K12 -> #DIV/0! | ... P14: =P13/P12 -> 0
A15: A0002 | B15: TWM | C15: Số bản vẽ | D15: 13 | E15: 13 | F15: 15 | P15: =SUM(D15:O15) -> 41
C16: Số phế phẩm | D16: 0 | E16: 0 | F16: 0 | P16: =SUM(D16:O16) -> 0
C17: Tỷ lệ phế phẩm | D17: =D16/D15 -> 0 | E17: =E16/E15 -> 0 | F17: =F16/F15 -> 0 | G17: =G16/G15 -> #DIV/0! | H17: =H16/H15 -> #DIV/0! | I17: =I16/I15 -> #DIV/0! | J17: =J16/J15 -> #DIV/0! | K17: =K16/K15 -> #DIV/0! | ... P17: =P16/P15 -> 0
A18: A0004 | B18: ＤＧＭ | C18: Số bản vẽ | D18: 8 | E18: 20 | F18: 40 | P18: =SUM(D18:O18) -> 68
C19: Số phế phẩm | D19: 0 | E19: 0 | F19: 0 | P19: =SUM(D19:O19) -> 0
C20: Tỷ lệ phế phẩm | D20: =D19/D18 -> 0 | E20: =E19/E18 -> 0 | F20: =F19/F18 -> 0 | G20: =G19/G18 -> #DIV/0! | H20: =H19/H18 -> #DIV/0! | I20: =I19/I18 -> #DIV/0! | J20: =J19/J18 -> #DIV/0! | K20: =K19/K18 -> #DIV/0! | ... P20: =P19/P18 -> 0
A21: A0005 | B21: TKM | C21: Số bản vẽ | D21: 12 | E21: 0 | F21: 12 | P21: =SUM(D21:O21) -> 24
C22: Số phế phẩm | D22: 0 | E22: 0 | F22: 0 | P22: =SUM(D22:O22) -> 0
C23: Tỷ lệ phế phẩm | D23: =D22/D21 -> 0 | E23: =E22/E21 -> #DIV/0! | F23: =F22/F21 -> 0 | G23: =G22/G21 -> #DIV/0! | H23: =H22/H21 -> #DIV/0! | I23: =I22/I21 -> #DIV/0! | J23: =J22/J21 -> #DIV/0! | K23: =K22/K21 -> #DIV/0! | ... P23: =P22/P21 -> 0
A24: VNM | B24: VNM | C24: Số bản vẽ | D24: 4 | E24: 3 | F24: 4 | P24: =SUM(D24:O24) -> 11
C25: Số phế phẩm | D25: 0 | E25: 0 | F25: 0 | P25: =SUM(D25:O25) -> 0
C26: Tỷ lệ phế phẩm | D26: =D25/D24 -> 0 | E26: =E25/E24 -> 0 | F26: =F25/F24 -> 0 | G26: =G25/G24 -> #DIV/0! | H26: =H25/H24 -> #DIV/0! | I26: =I25/I24 -> #DIV/0! | J26: =J25/J24 -> #DIV/0! | K26: =K25/K24 -> #DIV/0! | ... P26: =P25/P24 -> 0
A27: SP016 | B27: PUNCH | C27: Số bản vẽ | D27: 32 | E27: 9 | F27: 15 | P27: =SUM(D27:O27) -> 56
C28: Số phế phẩm | D28: 0 | E28: 0 | F28: 0 | P28: =SUM(D28:O28) -> 0
C29: Tỷ lệ phế phẩm | D29: =D28/D27 -> 0 | E29: =E28/E27 -> 0 | F29: =F28/F27 -> 0 | G29: =G28/G27 -> #DIV/0! | H29: =H28/H27 -> #DIV/0! | I29: =I28/I27 -> #DIV/0! | J29: =J28/J27 -> #DIV/0! | K29: =K28/K27 -> #DIV/0! | ... P29: =P28/P27 -> 0
A30: VD047 | B30: CAO SU VIET | C30: Số bản vẽ | D30: 0 | E30: 0 | F30: 0 | P30: =SUM(D30:O30) -> 0
C31: Số phế phẩm | D31: 0 | E31: 0 | F31: 0 | P31: =SUM(D31:O31) -> 0
C32: Tỷ lệ phế phẩm | D32: =D31/D30 -> #DIV/0! | E32: =E31/E30 -> #DIV/0! | F32: =F31/F30 -> #DIV/0! | G32: =G31/G30 -> #DIV/0! | H32: =H31/H30 -> #DIV/0! | I32: =I31/I30 -> #DIV/0! | J32: =J31/J30 -> #DIV/0! | K32: =K31/K30 -> #DIV/0! | ... P32: =P31/P30 -> #DIV/0!
A33: VD392 | B33: VINATECH | C33: Số bản vẽ | D33: 0 | E33: 0 | F33: 0 | P33: =SUM(D33:O33) -> 0
C34: Số phế phẩm | D34: 0 | E34: 0 | F34: 0 | P34: =SUM(D34:O34) -> 0
C35: Tỷ lệ phế phẩm | D35: =D34/D33 -> #DIV/0! | E35: =E34/E33 -> #DIV/0! | F35: =F34/F33 -> #DIV/0! | G35: =G34/G33 -> #DIV/0! | H35: =H34/H33 -> #DIV/0! | I35: =I34/I33 -> #DIV/0! | J35: =J34/J33 -> #DIV/0! | K35: =K34/K33 -> #DIV/0! | ... P35: =P34/P33 -> #DIV/0!
A36: VD069 | B36: KA SHIN | C36: Số bản vẽ | D36: 14 | E36: 0 | F36: 29 | P36: =SUM(D36:O36) -> 43
C37: Số phế phẩm | D37: 0 | E37: 0 | F37: 0 | P37: =SUM(D37:O37) -> 0
C38: Tỷ lệ phế phẩm | D38: =D37/D36 -> 0 | E38: =E37/E36 -> #DIV/0! | F38: =F37/F36 -> 0 | G38: =G37/G36 -> #DIV/0! | H38: =H37/H36 -> #DIV/0! | I38: =I37/I36 -> #DIV/0! | J38: =J37/J36 -> #DIV/0! | K38: =K37/K36 -> #DIV/0! | ... P38: =P37/P36 -> 0
A39: VD053 | B39: MINH THINH LOI | C39: Số bản vẽ | D39: 16 | E39: 3 | F39: 21 | P39: =SUM(D39:O39) -> 40
C40: Số phế phẩm | D40: 0 | E40: 0 | F40: 0 | P40: =SUM(D40:O40) -> 0
C41: Tỷ lệ phế phẩm | D41: =D40/D39 -> 0 | E41: =E40/E39 -> 0 | F41: =F40/F39 -> 0 | G41: =G40/G39 -> #DIV/0! | H41: =H40/H39 -> #DIV/0! | I41: =I40/I39 -> #DIV/0! | J41: =J40/J39 -> #DIV/0! | K41: =K40/K39 -> #DIV/0! | ... P41: =P40/P39 -> 0
A42: VD061 | B42: KIWA | C42: Số bản vẽ | D42: 103 | E42: 59 | F42: 64 | P42: =SUM(D42:O42) -> 226
...

Sheet 指標3（工程毎負荷時間)
E1: ☆月末時点の仕事の残工数を表しているものです。
E2: ①每天的负荷时间（分）图表的追加・・・可视化
F3: 相对工程能力的工程別負荷時間（日均）图表追加・・・可視化
E4: ②負荷日数图表的追加・・・仕掛天数的可視化
G5: ※目標値的追加・・・L/T短縮的意識
E6: ③图表是以切削系、研削系、放電系、NC系来分類・・・可視化
C8: 別紙4 | F8: 工程毎負荷時間（単位=分） | U8: 【自動入力】
D9: Ngày làm việc | E9: Day | F9: =機械別実績!L2 -> 22 | G9: =機械別実績!M2 -> 15 | H9: =機械別実績!N2 -> 22 | I9: =機械別実績!O2 -> 0 | J9: =機械別実績!P2 -> 0 | K9: =機械別実績!Q2 -> 0 | L9: =機械別実績!R2 -> 0 | M9: =機械別実績!S2 -> 0 | ... Q9: =機械別実績!W2 -> 0 | S9: １日工数 | T9: 910
E10: F,G | F10: =機械別実績!L3 -> 22 | G10: =機械別実績!M3 -> 15 | H10: =機械別実績!N3 -> 22 | I10: =機械別実績!O3 -> 0 | J10: =機械別実績!P3 -> 0 | K10: =機械別実績!Q3 -> 0 | L10: =機械別実績!R3 -> 0 | M10: =機械別実績!S3 -> 0 | ... Q10: =機械別実績!W3 -> 0
C11: 工程 | D11: 担当人数 | E11: 保有台数 | F11: 1月 | G11: 2月 | H11: 3月 | I11: 4月 | J11: 5月 | K11: 6月 | L11: 7月 | M11: 8月 | N11: 9月 | O11: 10月 | P11: 11月 | Q11: 12月 | S11: 工程 | T11: 担当人数 | U11: 保有台数 | V11: １日能力
B12: 切削系 | C12: LA | D12: 4 | E12: 3 | F12: 24467 | G12: 25947 | H12: 41367 | S12: LA | T12: =SUM(D12) -> 4 | U12: =SUM(E12) -> 3 | V12: =SUM($T$9*U12) -> 2730
C13: LN | D13: 4 | E13: 2 | F13: 135259 | G13: 127472 | H13: 130586 | S13: LN | T13: =SUM(D13) -> 4 | U13: =SUM(E13) -> 2 | V13: =SUM($T$9*U13) -> 1820
C14: MA | D14: 5 | E14: 4 | F14: 31666 | G14: 34927 | H14: 41214 | S14: MA | T14: =SUM(D14) -> 5 | U14: =SUM(E14) -> 4 | V14: =SUM($T$9*U14) -> 3640
C15: BJ | D15: 9 | E15: 5 | F15: 96199 | G15: 97510 | H15: 127753 | S15: BJ | T15: =SUM(D15) -> 9 | U15: =SUM(E15) -> 5 | V15: =SUM($T$9*U15) -> 4550
C16: DA | D16: 2 | E16: 2 | F16: 7558 | G16: 8294 | H16: 10671 | S16: DA | T16: =SUM(D16) -> 2 | U16: =SUM(E16) -> 2 | V16: =SUM($T$9*U16) -> 1820
C17: MC | D17: 6 | E17: 3 | F17: 151194 | G17: 150513 | H17: 150299 | S17: MC | T17: =SUM(D17) -> 6 | U17: =SUM(E17) -> 3 | V17: =SUM($T$9*U17) -> 2730
B18: 研削系 | C18: GS | D18: 12 | E18: 7 | F18: 202884 | G18: 202277 | H18: 231025 | S18: GS | T18: =SUM(D18) -> 12 | U18: =SUM(E18) -> 7 | V18: =SUM($T$9*U18) -> 6370
C19: GR | D19: 4 | E19: 2 | F19: 78541 | G19: 67492 | H19: 82005 | S19: GR | T19: =SUM(D19) -> 4 | U19: =SUM(E19) -> 2 | V19: =SUM($T$9*U19) -> 1820
A20: 保有無し | C20: GX | E20: 0 | S20: GX | T20: =SUM(D20) -> 0 | U20: =SUM(E20) -> 0 | V20: =SUM($T$9*U20) -> 0
C21: GC | D21: 2 | E21: 2 | F21: 66145 | G21: 65158 | H21: 68653 | S21: GC | T21: =SUM(D21) -> 2 | U21: =SUM(E21) -> 2 | V21: =SUM($T$9*U21) -> 1820
C22: GJ | D22: 2 | E22: 2 | F22: 48252 | G22: 42645 | H22: 53854 | S22: GJ | T22: =SUM(D22) -> 2 | U22: =SUM(E22) -> 2 | V22: =SUM($T$9*U22) -> 1820
C23: GP | D23: 4 | E23: 2 | F23: 90341 | G23: 83783 | H23: 73627 | S23: GP | T23: =SUM(D23) -> 4 | U23: =SUM(E23) -> 2 | V23: =SUM($T$9*U23) -> 1820
B24: 放電系 | C24: EN | D24: 6 | E24: 4 | F24: 146102 | G24: 141898 | H24: 158482 | S24: EN | T24: =SUM(D24) -> 6 | U24: =SUM(E24) -> 4 | V24: =SUM($T$9*U24) -> 3640
A25: 保有無し | C25: ES | E25: 0 | S25: ES | T25: =SUM(D25) -> 0 | U25: =SUM(E25) -> 0 | V25: =SUM($T$9*U25) -> 0
C26: EW | D26: 4 | E26: 4 | F26: 268692 | G26: 276264 | H26: 258135 | S26: EW | T26: =SUM(D26) -> 4 | U26: =SUM(E26) -> 4 | V26: =SUM($T$9*U26) -> 3640
C29: ※これより下側は【自動計算】なので入力不要
T30: Số người phụ trách
E31: ※自動計算 | G31: 455 | H31: 910
C32: １日当りの負荷時間 | E32: Day | F32: =F9 -> 22 | G32: =G9 -> 15 | H32: =H9 -> 22 | I32: =I9 -> 0 | J32: =J9 -> 0 | K32: =K9 -> 0 | L32: =L9 -> 0 | M32: =M9 -> 0 | ... Q32: =Q9 -> 0
E33: F,G | F33: =F10 -> 22 | G33: =G10 -> 15 | H33: =H10 -> 22 | I33: =I10 -> 0 | J33: =J10 -> 0 | K33: =K10 -> 0 | L33: =L10 -> 0 | M33: =M10 -> 0 | ... Q33: =Q10 -> 0
C34: 工程 | E34: 保有台数 | F34: 1月 | G34: 2月 | H34: 3月 | I34: 4月 | J34: 5月 | K34: 6月 | L34: 7月 | M34: 8月 | N34: 9月 | O34: 10月 | P34: 11月 | Q34: 12月
B35: 切削系 | C35: LA | D35: 負荷 | E35: =SUM(E12) -> 3 | F35: =SUM(F12/$E$35/F33) -> 370.71212 | G35: =SUM(G12/$E$35/G33) -> 576.6 | H35: =SUM(H12/$E$35/H33) -> 626.77273 | I35: =SUM(I12/$E$35/I33) -> #DIV/0! | J35: =SUM(J12/$E$35/J33) -> #DIV/0! | K35: =SUM(K12/$E$35/K33) -> #DIV/0! | L35: =SUM(L12/$E$35/L33) -> #DIV/0! | M35: =SUM(M12/$E$35/M33) -> #DIV/0! | ... Q35: =SUM(Q12/$E$35/Q33) -> #DIV/0!
C36: LA | D36: 能力 | E36: =SUM(E35) -> 3 | F36: =SUM($V$12) -> 2730 | G36: =SUM($V$12) -> 2730 | H36: =SUM($V$12) -> 2730 | I36: =SUM($V$12) -> 2730 | J36: =SUM($V$12) -> 2730 | K36: =SUM($V$12) -> 2730 | L36: =SUM($V$12) -> 2730 | M36: =SUM($V$12) -> 2730 | ... Q36: =SUM($V$12) -> 2730
C37: LN | D37: 負荷 | E37: =SUM(E13) -> 2 | F37: =SUM(F13/$E$37/F32) -> 3074.0682 | G37: =SUM(G13/$E$37/G32) -> 4249.0667 | H37: =SUM(H13/$E$37/H32) -> 2967.8636 | I37: =SUM(I13/$E$37/I32) -> #DIV/0! | J37: =SUM(J13/$E$37/J32) -> #DIV/0! | K37: =SUM(K13/$E$37/K32) -> #DIV/0! | L37: =SUM(L13/$E$37/L32) -> #DIV/0! | M37: =SUM(M13/$E$37/M32) -> #DIV/0! | ... Q37: =SUM(Q13/$E$37/Q32) -> #DIV/0!
C38: LN | D38: 能力 | E38: =SUM(E37) -> 2 | F38: =SUM($V$13) -> 1820 | G38: =SUM($V$13) -> 1820 | H38: =SUM($V$13) -> 1820 | I38: =SUM($V$13) -> 1820 | J38: =SUM($V$13) -> 1820 | K38: =SUM($V$13) -> 1820 | L38: =SUM($V$13) -> 1820 | M38: =SUM($V$13) -> 1820 | ... Q38: =SUM($V$13) -> 1820
C39: MA | D39: 負荷 | E39: =SUM(E14) -> 4 | F39: =SUM(F14/$E$39/F33) -> 359.84091 | G39: =SUM(G14/$E$39/G33) -> 582.11667 | H39: =SUM(H14/$E$39/H33) -> 468.34091 | I39: =SUM(I14/$E$39/I33) -> #DIV/0! | J39: =SUM(J14/$E$39/J33) -> #DIV/0! | K39: =SUM(K14/$E$39/K33) -> #DIV/0! | L39: =SUM(L14/$E$39/L33) -> #DIV/0! | M39: =SUM(M14/$E$39/M33) -> #DIV/0! | ... Q39: =SUM(Q14/$E$39/Q33) -> #DIV/0!
C40: MA | D40: 能力 | E40: =SUM(E39) -> 4 | F40: =SUM($V$14) -> 3640 | G40: =SUM($V$14) -> 3640 | H40: =SUM($V$14) -> 3640 | I40: =SUM($V$14) -> 3640 | J40: =SUM($V$14) -> 3640 | K40: =SUM($V$14) -> 3640 | L40: =SUM($V$14) -> 3640 | M40: =SUM($V$14) -> 3640 | ... Q40: =SUM($V$14) -> 3640
C41: BJ | D41: 負荷 | E41: =SUM(E15) -> 5 | F41: =SUM(F15/$E$41/F33) -> 874.53636 | G41: =SUM(G15/$E$41/G33) -> 1300.1333 | H41: =SUM(H15/$E$41/H33) -> 1161.3909 | I41: =SUM(I15/$E$41/I33) -> #DIV/0! | J41: =SUM(J15/$E$41/J33) -> #DIV/0! | K41: =SUM(K15/$E$41/K33) -> #DIV/0! | L41: =SUM(L15/$E$41/L33) -> #DIV/0! | M41: =SUM(M15/$E$41/M33) -> #DIV/0! | ... Q41: =SUM(Q15/$E$41/Q33) -> #DIV/0!
C42: BJ | D42: 能力 | E42: =SUM(E41) -> 5 | F42: =SUM($V$15) -> 4550 | G42: =SUM($V$15) -> 4550 | H42: =SUM($V$15) -> 4550 | I42: =SUM($V$15) -> 4550 | J42: =SUM($V$15) -> 4550 | K42: =SUM($V$15) -> 4550 | L42: =SUM($V$15) -> 4550 | M42: =SUM($V$15) -> 4550 | ... Q42: =SUM($V$15) -> 4550
C43: DA | D43: 負荷 | E43: =SUM(E16) -> 2 | F43: =SUM(F16/$E$43/F33) -> 171.77273 | G43: =SUM(G16/$E$43/G33) -> 276.46667 | H43: =SUM(H16/$E$43/H33) -> 242.52273 | I43: =SUM(I16/$E$43/I33) -> #DIV/0! | J43: =SUM(J16/$E$43/J33) -> #DIV/0! | K43: =SUM(K16/$E$43/K33) -> #DIV/0! | L43: =SUM(L16/$E$43/L33) -> #DIV/0! | M43: =SUM(M16/$E$43/M33) -> #DIV/0! | ... Q43: =SUM(Q16/$E$43/Q33) -> #DIV/0!
...

Sheet 指標４（生産性) 
A1: Khẩu hiệu :Bố trí an toàn và nâng cao tỷ lệ hoạt động không người
A2: Tuyên bố :Nâng cao tỷ lệ hoạt động không người | I2: 無人稼働率の目標達成率
A3: Trị mục tiêu:20.0% | H3: Mục tiêu | I3: Tháng 1 | J3: Tháng 2 | K3: Tháng 3 | L3: Tháng 4 | M3: Tháng 5 | N3: Tháng 6 | O3: Tháng 7 | P3: Tháng 8 | Q3: Tháng 9 | R3: Tháng 10 | S3: Tháng 11 | T3: Tháng 12 | U3: Trung bình
H4: 20 | I4: =I20/$H$4 -> 0.78430779 | J4: =J20/$H$4 -> 1.0187948 | K4: =K20/$H$4 -> 1.1621958 | L4: =L20/$H$4 -> #DIV/0! | M4: =M20/$H$4 -> #DIV/0! | N4: =N20/$H$4 -> #DIV/0! | O4: =O20/$H$4 -> #DIV/0! | P4: =P20/$H$4 -> #DIV/0! | ... U4: =U20/$H$4 -> 0.97877213
I5: 1Q | L5: 2Q | O5: 3Q | R5: 4Q
I6: =(((I19+J19+K19)/(I17+J17+K17))/$H$4*100) -> 0.97877213 | L6: =(((L19+M19+N19)/(L17+M17+N17))/$H$4*100) -> #DIV/0! | O6: =(((O19+P19+Q19)/(O17+P17+Q17))/$H$4*100) -> #DIV/0! | R6: =(((R19+S19+T19)/(R17+S17+T17))/$H$4*100) -> #DIV/0!
H7: 自動計算 | I7: Tháng 1 | J7: Tháng 2 | K7: Tháng 3 | L7: Tháng 4 | M7: Tháng 5 | N7: Tháng 6 | O7: Tháng 7 | P7: Tháng 8 | Q7: Tháng 9 | R7: Tháng 10 | S7: Tháng 11 | T7: Tháng 12
C8: 項目 | G8: 計算式 | I8: 1月 | J8: 2月 | K8: 3月 | L8: 4月 | M8: 5月 | N8: 6月 | O8: 7月 | P8: 8月 | Q8: 9月 | R8: 10月 | S8: 11月 | T8: 12月 | U8: 平均 | V8: 備 考
A9: １．人 | B9: a | C9: 総人数 （合計） | D9: Tổng số người | E9: 単月 | F9: đơn tháng | H9: 実績 | I9: 89 | J9: 89 | K9: 90
B10: b | C10: 加工者人数 | D10: NV gia công | H10: 実績 | I10: 72 | J10: 72 | K10: 71
B11: c | C11: その他の人数 | D11: NV khác | G11: c=a-b | H11: 実績 | I11: =I9-I10 -> 17 | J11: =J9-J10 -> 17 | K11: =K9-K10 -> 19 | L11: =L9-L10 -> 0 | M11: =M9-M10 -> 0 | N11: =N9-N10 -> 0 | O11: =O9-O10 -> 0 | P11: =P9-P10 -> 0 | ... T11: =T9-T10 -> 0
A12: ２．時間 | B12: d | C12: 稼働日数 | D12: số ngày làm việc | E12: 単月 | F12: đơn tháng | G12: d=機械別実績 (2) | H12: 実績 | I12: =機械別実績!L2 -> 22 | J12: =機械別実績!M2 -> 15 | K12: =機械別実績!N2 -> 22 | L12: =機械別実績!O2 -> 0 | M12: =機械別実績!P2 -> 0 | N12: =機械別実績!Q2 -> 0 | O12: =機械別実績!R2 -> 0 | P12: =機械別実績!S2 -> 0 | ... T12: =機械別実績!W2 -> 0
B13: e | C13: 直接人実労働時間 (h) ※残業時間含む | D13: tong TGLV cua NVTT | E13: 単月 | F13: đơn tháng | H13: 実績 | I13: 13971 | J13: 9500 | K13: 14088 | U13: =SUM(I13:T13) -> 37559 | V13: （b：加工者人数） 残業を含む総労働時間
B14: f | E14: 累計 | F14: lũy kế | H14: 実績 | I14: =I13 -> 13971 | J14: =I14+J13 -> 23471 | K14: =J14+K13 -> 37559 | L14: =K14+L13 -> 37559 | M14: =L14+M13 -> 37559 | N14: =M14+N13 -> 37559 | O14: =N14+O13 -> 37559 | P14: =O14+P13 -> 37559 | Q14: =P14+Q13 -> 37559 | ... T14: =S14+T13 -> 37559
B15: g | C15: １人/日 平均稼働時間 | D15: thoi gian LV trung binh 1 nguoi/ ngay | E15: 単月 | F15: đơn tháng | G15: g=e/d/b | H15: 実績 | I15: =SUM(I13/I12/I10) -> 8.8200758 | J15: =SUM(J13/J12/J10) -> 8.7962963 | K15: =SUM(K13/K12/K10) -> 9.0192061 | L15: =SUM(L13/L12/L10) -> #DIV/0! | M15: =SUM(M13/M12/M10) -> #DIV/0! | N15: =SUM(N13/N12/N10) -> #DIV/0! | O15: =SUM(O13/O12/O10) -> #DIV/0! | P15: =SUM(P13/P12/P10) -> #DIV/0! | ... T15: =SUM(T13/T12/T10) -> #DIV/0!
B16: h | C16: 実加工時間 （h） | D16: Tong TGTD | E16: 単月 | F16: đơn tháng | H16: 予定 | I16: 16661 | J16: 10947.8 | K16: 16560.883 | V16: 標準時間
B17: i | H17: 実績 | I17: 16505 | J17: 10318.483 | K17: 15247 | U17: =SUM(I17:T17) -> 42070.483 | V17: 機械稼働時間＋手仕上げ等の合計時間
B18: j | C18: 有人稼働時間 | D18: TGLV có nguoi | E18: 単月 | F18: đơn tháng | H18: 実績 | I18: 13916 | J18: 8216 | K18: 11703 | V18: ( i：実加工時間)の内、有人での稼働時間
B19: k | C19: 無人稼働時間 | D19: TGLV ko nguoi | E19: 単月 | F19: đơn tháng | G19: k=i-j | H19: 実績 | I19: =I17-I18 -> 2589 | J19: =J17-J18 -> 2102.4833 | K19: =K17-K18 -> 3544 | L19: =L17-L18 -> 0 | M19: =M17-M18 -> 0 | N19: =N17-N18 -> 0 | O19: =O17-O18 -> 0 | P19: =P17-P18 -> 0 | ... T19: =T17-T18 -> 0 | U19: =SUM(I19:T19) -> 8235.4833
B20: ◎ | C20: 無人稼働率(%) | D20: Tỉ lệ hoạt động ko nguoi | E20: 単月 | F20: đơn tháng | G20: ◎=k/i*100 | I20: =I19/I17*100 -> 15.686156 | J20: =J19/J17*100 -> 20.375895 | K20: =K19/K17*100 -> 23.243917 | L20: =L19/L17*100 -> #DIV/0! | M20: =M19/M17*100 -> #DIV/0! | N20: =N19/N17*100 -> #DIV/0! | O20: =O19/O17*100 -> #DIV/0! | P20: =P19/P17*100 -> #DIV/0! | ... U20: =U19/U17*100 -> 19.575443
B21: l | C21: 加工効率 | D21: hieu suat gia cong | E21: 単月 | F21: đơn tháng | G21: l=i/h | H21: 実績 | I21: =I17/I16 -> 0.99063682 | J21: =J17/J16 -> 0.94251661 | K21: =K17/K16 -> 0.92066345 | L21: =L17/L16 -> #DIV/0! | M21: =M17/M16 -> #DIV/0! | N21: =N17/N16 -> #DIV/0! | O21: =O17/O16 -> #DIV/0! | P21: =P17/P16 -> #DIV/0! | ... T21: =T17/T16 -> #DIV/0!
B22: m | C22: 総労働時間当たり加工工数 | D22: số công GC tương ứng với TGLV | E22: 単月 | F22: đơn tháng | G22: m=i/e | H22: 実績 | I22: =I17/I13 -> 1.1813757 | J22: =J17/J13 -> 1.0861561 | K22: =K17/K13 -> 1.0822686 | L22: =L17/L13 -> #DIV/0! | M22: =M17/M13 -> #DIV/0! | N22: =N17/N13 -> #DIV/0! | O22: =O17/O13 -> #DIV/0! | P22: =P17/P13 -> #DIV/0! | ... U22: =U17/U13 -> 1.1201172
B23: n | C23: 目標値（生産拠点指数） | D23: mục tiêu sô công gia công tương ứng với TGLV | H23: 目標値【1.1】 | I23: 1.1 | J23: 1.1 | K23: 1.1 | L23: 1.1 | M23: 1.1 | N23: 1.1 | O23: 1.1 | P23: 1.1 | Q23: 1.1 | R23: 1.1 | S23: 1.1 | T23: 1.1
A24: ３．品質 | B24: o | C24: 不良件数（枚） | D24: số kiện PP | E24: 単月 | F24: đơn tháng | G24: o=指標2（内作）C10 ALL不良件数 | H24: 実績 | I24: ='指標２(内作)'!C10 -> 0 | J24: ='指標２(内作)'!D10 -> 0 | K24: ='指標２(内作)'!E10 -> 1 | L24: ='指標２(内作)'!F10 -> 0 | M24: ='指標２(内作)'!G10 -> 0 | N24: ='指標２(内作)'!H10 -> 0 | O24: ='指標２(内作)'!I10 -> 0 | P24: ='指標２(内作)'!J10 -> 0 | ... T24: ='指標２(内作)'!N10 -> 0
B25: p | C25: 不良工数（ｈ） | D25: sô công PP | H25: 実績 | I25: 0 | J25: 0 | K25: 5.8 | V25: 不良をﾘｶﾊﾞﾘｰする為にかかった時間
B26: q | C26: 総加工時間 （h） | D26: TTGGC | G26: q=i | H26: 実績 | I26: =I17 -> 16505 | J26: =J17 -> 10318.483 | K26: =K17 -> 15247 | L26: =L17 -> 0 | M26: =M17 -> 0 | N26: =N17 -> 0 | O26: =O17 -> 0 | P26: =P17 -> 0 | ... T26: =T17 -> 0
B27: r | C27: 不良工数率（％） | D27: tỉ lệ số công PP | G27: r=p/q | H27: 実績 | I27: =SUM(I25/I26) -> 0 | J27: =SUM(J25/J26) -> 0 | K27: =SUM(K25/K26) -> 0.0003804027 | L27: =SUM(L25/L26) -> #DIV/0! | M27: =SUM(M25/M26) -> #DIV/0! | N27: =SUM(N25/N26) -> #DIV/0! | O27: =SUM(O25/O26) -> #DIV/0! | P27: =SUM(P25/P26) -> #DIV/0! | ... T27: =SUM(T25/T26) -> #DIV/0!
A28: ４．コスト | B28: s | C28: 1人当たりの加工工数（h） | D28: TGGC 1 nguoi | E28: 単月 | F28: đơn tháng | G28: s=q/b | H28: 実績 | I28: =SUM(I26/I10) -> 229.23611 | J28: =SUM(J26/J10) -> 143.31227 | K28: =SUM(K26/K10) -> 214.74648 | L28: =SUM(L26/L10) -> #DIV/0! | M28: =SUM(M26/M10) -> #DIV/0! | N28: =SUM(N26/N10) -> #DIV/0! | O28: =SUM(O26/O10) -> #DIV/0! | P28: =SUM(P26/P10) -> #DIV/0! | ... T28: =SUM(T26/T10) -> #DIV/0!
B29: t | C29: １人当たりの加工個数（Pcs） | D29: số pcs hoan thanh 1 nguoi | G29: t=w/b | H29: 実績 | I29: =SUM(I32/I10) -> 473.59722 | J29: =SUM(J32/J10) -> 277.16667 | K29: =SUM(K32/K10) -> 494.70423 | L29: =SUM(L32/L10) -> #DIV/0! | M29: =SUM(M32/M10) -> #DIV/0! | N29: =SUM(N32/N10) -> #DIV/0! | O29: =SUM(O32/O10) -> #DIV/0! | P29: =SUM(P32/P10) -> #DIV/0! | ... T29: =SUM(T32/T10) -> #DIV/0!
A30: ５．生産性 (内作) | B30: u | C30: 完成総図面数量 (枚) | D30: tông bv hoan thanh | E30: 単月 | F30: đơn tháng | G30: u=指標1 (B29) 内作完了図面枚数 | H30: 実績 | I30: =指標1!B29 -> 2412 | J30: =指標1!C29 -> 1563 | K30: =指標1!D29 -> 2232 | L30: =指標1!E29 -> 0 | M30: =指標1!F29 -> 0 | N30: =指標1!G29 -> 0 | O30: =指標1!H29 -> 0 | P30: =指標1!I29 -> 0 | ... T30: =指標1!M29 -> 0
B31: v | E31: 累計 | F31: lũy kế | H31: 実績 | I31: =I30 -> 2412 | J31: =I31+J30 -> 3975 | K31: =J31+K30 -> 6207 | L31: =K31+L30 -> 6207 | M31: =L31+M30 -> 6207 | N31: =M31+N30 -> 6207 | O31: =N31+O30 -> 6207 | P31: =O31+P30 -> 6207 | Q31: =P31+Q30 -> 6207 | ... T31: =S31+T30 -> 6207
B32: w | C32: 完成総数量 (Pcs) | D32: tong pcs hoan thanh | E32: 単月 | F32: đơn tháng | G32: w=指標1 (B14) 内作完成数量 | H32: 実績 | I32: =指標1!B14 -> 34099 | J32: =指標1!C14 -> 19956 | K32: =指標1!D14 -> 35124 | L32: =指標1!E14 -> 0 | M32: =指標1!F14 -> 0 | N32: =指標1!G14 -> 0 | O32: =指標1!H14 -> 0 | P32: =指標1!I14 -> 0 | ... T32: =指標1!M14 -> 0
B33: x | E33: 累計 | F33: lũy kế | H33: 実績 | I33: =I32 -> 34099 | J33: =I33+J32 -> 54055 | K33: =J33+K32 -> 89179 | L33: =K33+L32 -> 89179 | M33: =L33+M32 -> 89179 | N33: =M33+N32 -> 89179 | O33: =N33+O32 -> 89179 | P33: =O33+P32 -> 89179 | Q33: =P33+Q32 -> 89179 | ... T33: =S33+T32 -> 89179
B34: y | C34: P/M.H 値 (図面） | D34: chi số bv/ M.H | E34: 単月 | F34: đơn tháng | G34: y=u/e | H34: 実績 | I34: =I30/I13 -> 0.17264333 | J34: =J30/J13 -> 0.16452632 | K34: =K30/K13 -> 0.15843271 | L34: =L30/L13 -> #DIV/0! | M34: =M30/M13 -> #DIV/0! | N34: =N30/N13 -> #DIV/0! | O34: =O30/O13 -> #DIV/0! | P34: =P30/P13 -> #DIV/0! | ... T34: =T30/T13 -> #DIV/0!
B35: z | E35: 累計 | F35: lũy kế | G35: z=v/f | H35: 実績 | I35: =I31/I14 -> 0.17264333 | J35: =J31/J14 -> 0.16935793 | K35: =K31/K14 -> 0.16525999 | L35: =L31/L14 -> 0.16525999 | M35: =M31/M14 -> 0.16525999 | N35: =N31/N14 -> 0.16525999 | O35: =O31/O14 -> 0.16525999 | P35: =P31/P14 -> 0.16525999 | ... T35: =T31/T14 -> 0.16525999
B36: A | C36: P/M.H 値 (Ｐｃｓ) | D36: chi sô pcs /M.H | E36: 単月 | F36: đơn tháng | G36: A=w/e | H36: 実績 | I36: =I32/I13 -> 2.4406986 | J36: =J32/J13 -> 2.1006316 | K36: =K32/K13 -> 2.4931857 | L36: =L32/L13 -> #DIV/0! | M36: =M32/M13 -> #DIV/0! | N36: =N32/N13 -> #DIV/0! | O36: =O32/O13 -> #DIV/0! | P36: =P32/P13 -> #DIV/0! | ... T36: =T32/T13 -> #DIV/0!
B37: B | E37: 累計 | F37: lũy kế | G37: B=x/f | H37: 実績 | I37: =I33/I14 -> 2.4406986 | J37: =J33/J14 -> 2.3030548 | K37: =K33/K14 -> 2.374371 | L37: =L33/L14 -> 2.374371 | M37: =M33/M14 -> 2.374371 | N37: =N33/N14 -> 2.374371 | O37: =O33/O14 -> 2.374371 | P37: =P33/P14 -> 2.374371 | ... T37: =T33/T14 -> 2.374371
B38: C | C38: 加工完了金額 (単位) | D38: sô tiền GCHT | E38: 単月 | F38: đơn tháng | H38: 実績 | I38: 148863 | J38: 103593.85 | K38: 114471
B39: D | E39: 累計 | F39: lũy kế | H39: 実績 | I39: =I38 -> 148863 | J39: =I39+J38 -> 252456.85 | K39: =J39+K38 -> 366927.85 | L39: =K39+L38 -> 366927.85 | M39: =L39+M38 -> 366927.85 | N39: =M39+N38 -> 366927.85 | O39: =N39+O38 -> 366927.85 | P39: =O39+P38 -> 366927.85 | Q39: =P39+Q38 -> 366927.85 | ... T39: =S39+T38 -> 366927.85
B40: E | C40: 加工費/M.H (単位) | D40: số tiền GC / M.H | E40: 単月 | F40: đơn tháng | G40: E=C/e | H40: 実績 | I40: =I38/I13 -> 10.655143 | J40: =J38/J13 -> 10.904615 | K40: =K38/K13 -> 8.1254259 | L40: =L38/L13 -> #DIV/0! | M40: =M38/M13 -> #DIV/0! | N40: =N38/N13 -> #DIV/0! | O40: =O38/O13 -> #DIV/0! | P40: =P38/P13 -> #DIV/0! | ... T40: =T38/T13 -> #DIV/0!
...
